Workbook

Sheet Свод
A3: Показатель | B3: Категория хозяйства | C3: Регион | D3: 42005 | E3: 42036 | F3: 42064 | G3: 42095 | H3: 42125 | I3: 42156 | J3: 42186 | K3: 42217 | L3: 42248 | M3: 42278 | N3: 42309 | O3: 42339 | P3: 42370 | Q3: 42401 | R3: 42430 | S3: 42461 | T3: 42491 | U3: 42522 | V3: 42552 | W3: 42583 | X3: 42614 | Y3: 42644 | Z3: 42675 | AA3: 42705 | AB3: 42736 | AC3: 42767 | AD3: 42795 | AE3: 42826 | AF3: 42856 | AG3: 42887 | AH3: 42917 | AI3: 42948 | AJ3: 42979 | AK3: 43009 | AL3: 43040 | AM3: 43070 | AN3: 43101 | AO3: 43132 | AP3: 43160 | AQ3: 43191 | AR3: 43221 | AS3: 43252 | AT3: 43282 | AU3: 43313 | AV3: 43344 | AW3: 43374 | AX3: 43405 | AY3: 43435 | AZ3: 43466 | BA3: 43497 | BB3: 43525 | BC3: 43556 | BD3: 43586 | BE3: 43617 | BF3: 43647 | BG3: 43678 | BH3: 43709 | BI3: 43739 | BJ3: 43770 | BK3: 43800 | BL3: 43831 | BM3: 43862 | BN3: 43891 | BO3: 43922 | BP3: 43952 | BQ3: 43983 | BR3: 44013 | BS3: 44044 | BT3: 44075 | BU3: 44105 | BV3: 44136 | BW3: 44166 | BX3: 44197 | BY3: 44228 | BZ3: 44256 | CA3: 44287 | CB3: 44317 | CC3: 44348 | CD3: 44378 | CE3: 44409 | CF3: 44440 | CG3: 44470 | CH3: 44501 | CI3: 44531 | CJ3: 44562 | CK3: 44593 | CL3: 44621 | CM3: 44652 | CN3: 44682 | CO3: 44713 | CP3: 44743 | CQ3: 44774 | CR3: 44805 | CS3: 44835 | CT3: 44866 | CU3: 44896 | CV3: 44927 | CW3: 44958 | CX3: 44986 | CY3: 45017 | CZ3: 45047 | DA3: 45078 | DB3: 45108 | DC3: 45139 | DD3: 45170 | DE3: 45200 | DF3: 45231 | DG3: 45261 | DH3: 45292 | DI3: 45323 | DJ3: 45352 | DK3: 45383 | DL3: 45413 | DM3: 45444 | DN3: 45474 | DO3: 45505 | DP3: 45536 | DQ3: 45566 | DR3: 45597 | DS3: 45627 | DT3: 45658 | DU3: 45689 | DV3: 45717 | DW3: 45748 | DX3: 45778 | DY3: 45809 | DZ3: 45839
A4: КРС | B4: Сельхозпредприятия | C4: РЕСПУБЛИКА КАЗАХСТАН | D4: 3400.96 | E4: 3685.9 | F4: 4154.43 | G4: 5203.94 | H4: 5084.05 | I4: 6718.83 | J4: 4235.03 | K4: 4014.95 | L4: 4907.52 | M4: 4274.75 | N4: 3858.39 | O4: 6477.35 | P4: 3884.84 | Q4: 4146.9 | R4: 4282.08 | S4: 5408.9 | T4: 4390.56 | U4: 8005.48 | V4: 5105.84 | W4: 4700.12 | X4: 5548.88 | Y4: 3958.09 | Z4: 6264.34 | AA4: 9196.32 | AB4: 3739.75 | AC4: 4951.17 | AD4: 6316.68 | AE4: 5751.36 | AF4: 5747.16 | AG4: 10114.01 | AH4: 5944.43 | AI4: 6768.61 | AJ4: 5781.59 | AK4: 5885.5 | AL4: 7429.34 | AM4: 9411.91 | AN4: 5555.9 | AO4: 4586.48 | AP4: 7970.28 | AQ4: 8130.34 | AR4: 8048.48 | AS4: 14491.87 | AT4: 7543.26 | AU4: 7396.97 | AV4: 9668.6 | AW4: 6730.17 | AX4: 7987.91 | AY4: 11121.61 | AZ4: 5666.49 | BA4: 5917.68 | BB4: 8899.55 | BC4: 7784.95 | BD4: 9167.13 | BE4: 16299.73 | BF4: 7164.2 | BG4: 7341.17 | BH4: 10162.65 | BI4: 13532.56 | BJ4: 11737.17 | BK4: 14948.7 | BL4: 7041.38 | BM4: 4341.74 | BN4: 10336.12 | BO4: 7419.05 | BP4: 10452.61 | BQ4: 16413.66 | BR4: 7973.85 | BS4: 8901.52 | BT4: 10934.83 | BU4: 13130.82 | BV4: 12848.98 | BW4: 18882.81 | BX4: 8135.62 | BY4: 6432.18 | BZ4: 9650.38 | CA4: 10482.45 | CB4: 11405.76 | CC4: 16121.49 | CD4: 9114.93 | CE4: 14885.29 | CF4: 13567.02 | CG4: 13473.97 | CH4: 12558.44 | CI4: 20382.82 | CJ4: 6709.4 | CK4: 8554.71 | CL4: 12487.58 | CM4: 9184.25 | CN4: 7094.7 | CO4: 16471.11 | CP4: 6373.02 | CQ4: 10145.08 | CR4: 8831.12 | CS4: 11123 | CT4: 8927.05 | CU4: 11379.06 | CV4: 7452.75 | CW4: 6836.85 | CX4: 8719.53 | CY4: 9925.26 | CZ4: 7684.37 | DA4: 12218.39 | DB4: 6460.2 | DC4: 11289.58 | DD4: 15156.55 | DE4: 9790.74 | DF4: 9021.76 | DG4: 13193.63 | DH4: 6799.94 | DI4: 12303.66 | DJ4: 9703.45 | DK4: 11165.56 | DL4: 8179.14 | DM4: 24407.52 | DN4: 9835.22 | DO4: 11955.41 | DP4: 16955.56 | DQ4: 10638.42 | DR4: 9612.92 | DS4: 21521.5 | DT4: 6844.96 | DU4: 6687.71 | DV4: 8238.73 | DW4: 7324.04 | DX4: 7044.61 | DY4: 14116.34 | DZ4: 10179.94
A5: КРС | B5: Сельхозпредприятия | C5: АКМОЛИНСКАЯ ОБЛАСТЬ | D5: 514.75 | E5: 497.95 | F5: 863.93 | G5: 667.81 | H5: 633.39 | I5: 600.86 | J5: 875.47 | K5: 942.18 | L5: 856.9 | M5: 981.04 | N5: 873.89 | O5: 1390.18 | P5: 736.62 | Q5: 845.64 | R5: 774.36 | S5: 618.97 | T5: 701.72 | U5: 796.48 | V5: 914.5 | W5: 736.52 | X5: 897.89 | Y5: 912.46 | Z5: 867.99 | AA5: 1102.48 | AB5: 660.12 | AC5: 731.14 | AD5: 835 | AE5: 860.71 | AF5: 883.43 | AG5: 963.32 | AH5: 745.3 | AI5: 844.01 | AJ5: 678 | AK5: 1025.12 | AL5: 1312.34 | AM5: 919.29 | AN5: 670.25 | AO5: 942.66 | AP5: 847.27 | AQ5: 907.92 | AR5: 1002.24 | AS5: 911.62 | AT5: 873.09 | AU5: 1070.9 | AV5: 938.24 | AW5: 832.71 | AX5: 780.14 | AY5: 792.74 | AZ5: 993.76 | BA5: 1044.12 | BB5: 1250.31 | BC5: 892.18 | BD5: 1441.82 | BE5: 1249.59 | BF5: 822.67 | BG5: 1007.64 | BH5: 1333 | BI5: 1160.5 | BJ5: 1088.61 | BK5: 1164.95 | BL5: 782.49 | BM5: 829.6 | BN5: 1780.71 | BO5: 1077.39 | BP5: 1145.56 | BQ5: 1100.69 | BR5: 898.78 | BS5: 829.67 | BT5: 930.63 | BU5: 1135.02 | BV5: 1025.99 | BW5: 1133.29 | BX5: 1141.02 | BY5: 957.47 | BZ5: 1261.8 | CA5: 979.49 | CB5: 1029.19 | CC5: 864.06 | CD5: 1056.22 | CE5: 1019.37 | CF5: 1028.55 | CG5: 1254.05 | CH5: 1025.9 | CI5: 1062.94 | CJ5: 537.96 | CK5: 1089 | CL5: 1631.34 | CM5: 1183.73 | CN5: 1118.31 | CO5: 1064.21 | CP5: 1240.11 | CQ5: 1000.26 | CR5: 1269.72 | CS5: 1136.14 | CT5: 1230.95 | CU5: 1026.95 | CV5: 1294.11 | CW5: 936.76 | CX5: 1229.11 | CY5: 1048.76 | CZ5: 1040.48 | DA5: 1181.82 | DB5: 869.84 | DC5: 993.64 | DD5: 938.85 | DE5: 1102.67 | DF5: 1001.63 | DG5: 1079.39 | DH5: 972.07 | DI5: 938.35 | DJ5: 978.41 | DK5: 1071.35 | DL5: 1067.76 | DM5: 1119.61 | DN5: 898.07 | DO5: 1382 | DP5: 1133.36 | DQ5: 1073.27 | DR5: 1118.19 | DS5: 1332.88 | DT5: 837.79 | DU5: 1082.43 | DV5: 1426.73 | DW5: 1238.21 | DX5: 1262.37 | DY5: 1269.83 | DZ5: 1261.41
A6: КРС | B6: Сельхозпредприятия | C6: АКТЮБИНСКАЯ ОБЛАСТЬ | D6: 554.41 | E6: 504.35 | F6: 493.56 | G6: 445.51 | H6: 585.79 | I6: 316.47 | J6: 469.49 | K6: 303.09 | L6: 685.51 | M6: 600.85 | N6: 603.26 | O6: 700.48 | P6: 477.84 | Q6: 221.08 | R6: 265.59 | S6: 328.03 | T6: 384.03 | U6: 555.07 | V6: 615.9 | W6: 619.33 | X6: 770.79 | Y6: 302.27 | Z6: 1076.31 | AA6: 862.54 | AB6: 473.66 | AC6: 475.3 | AD6: 814.18 | AE6: 638.87 | AF6: 642.96 | AG6: 834.97 | AH6: 902.65 | AI6: 701.17 | AJ6: 756.63 | AK6: 726.68 | AL6: 654.31 | AM6: 801.49 | AN6: 703.32 | AO6: 514.47 | AP6: 952.16 | AQ6: 1018.39 | AR6: 968.68 | AS6: 845.85 | AT6: 758.18 | AU6: 931.47 | AV6: 1070.07 | AW6: 1278.41 | AX6: 1627.73 | AY6: 1714.64 | AZ6: 704.51 | BA6: 899.66 | BB6: 1554.1 | BC6: 1351.44 | BD6: 1050.71 | BE6: 1485.45 | BF6: 814.13 | BG6: 1169.81 | BH6: 2388.34 | BI6: 1595.4 | BJ6: 3809.76 | BK6: 3510.19 | BL6: 954.53 | BM6: 481.35 | BN6: 1111.55 | BO6: 1033.96 | BP6: 1939.87 | BQ6: 2152.47 | BR6: 1578.87 | BS6: 1426.39 | BT6: 2620.87 | BU6: 2434.4 | BV6: 3247.3 | BW6: 3281.67 | BX6: 580.89 | BY6: 823.34 | BZ6: 1221.21 | CA6: 1626.06 | CB6: 1920.41 | CC6: 2637.56 | CD6: 1620.81 | CE6: 2134.96 | CF6: 3425.67 | CG6: 3449.02 | CH6: 3751.75 | CI6: 3827.39 | CJ6: 826.17 | CK6: 1132.81 | CL6: 1544.91 | CM6: 1885.46 | CN6: 698.01 | CO6: 4712.69 | CP6: 508.07 | CQ6: 592.19 | CR6: 902.26 | CS6: 1479.36 | CT6: 1219.25 | CU6: 658.78 | CV6: 589.8 | CW6: 1275.24 | CX6: 1508.27 | CY6: 1380.18 | CZ6: 842.24 | DA6: 3478.29 | DB6: 774.46 | DC6: 764.8 | DD6: 3003.94 | DE6: 1876.68 | DF6: 1547.77 | DG6: 607.03 | DH6: 609.08 | DI6: 873.05 | DJ6: 1520.51 | DK6: 1747.09 | DL6: 915.8 | DM6: 1851.96 | DN6: 932.63 | DO6: 945.11 | DP6: 1142.92 | DQ6: 1637.64 | DR6: 1180.54 | DS6: 1045.69 | DT6: 526.84 | DU6: 627.83 | DV6: 1314.81 | DW6: 1509.41 | DX6: 743.94 | DY6: 1543.76 | DZ6: 570.04
A7: КРС | B7: Сельхозпредприятия | C7: АЛМАТИНСКАЯ ОБЛАСТЬ | D7: 178.3 | E7: 362.86 | F7: 352.49 | G7: 451.79 | H7: 228.32 | I7: 708.84 | J7: 280.55 | K7: 126.59 | L7: 629.44 | M7: 314.28 | N7: 302.7 | O7: 273.87 | P7: 362.96 | Q7: 524.37 | R7: 549.52 | S7: 1221.29 | T7: 663.04 | U7: 1033.44 | V7: 877.53 | W7: 795.88 | X7: 549.7 | Y7: 524.17 | Z7: 762.84 | AA7: 909.95 | AB7: 361.53 | AC7: 659.43 | AD7: 489.3 | AE7: 413.05 | AF7: 901.47 | AG7: 633.54 | AH7: 986.07 | AI7: 1245.53 | AJ7: 678.11 | AK7: 462.36 | AL7: 1124.24 | AM7: 1042.7 | AN7: 626.23 | AO7: 691.69 | AP7: 900.64 | AQ7: 546.92 | AR7: 753.49 | AS7: 1249.22 | AT7: 870.13 | AU7: 1085.25 | AV7: 767.07 | AW7: 833.67 | AX7: 621.67 | AY7: 1270.71 | AZ7: 647.57 | BA7: 859.73 | BB7: 627.58 | BC7: 510.15 | BD7: 1060.85 | BE7: 748.1 | BF7: 795.62 | BG7: 713.09 | BH7: 917.57 | BI7: 2486.33 | BJ7: 1047.68 | BK7: 1716.96 | BL7: 138.84 | BM7: 193.57 | BN7: 1915.13 | BO7: 318.06 | BP7: 1376.06 | BQ7: 1100.94 | BR7: 732.62 | BS7: 403.93 | BT7: 1133.23 | BU7: 296.33 | BV7: 528.96 | BW7: 765.77 | BX7: 256.65 | BY7: 247.48 | BZ7: 1642.59 | CA7: 204.04 | CB7: 1358.42 | CC7: 1168.3 | CD7: 299.38 | CE7: 1286.74 | CF7: 482.08 | CG7: 219.4 | CH7: 455.71 | CI7: 342.51 | CJ7: 185.09 | CK7: 235.07 | CL7: 1692.44 | CM7: 276.34 | CN7: 475.5 | CO7: 1043.31 | CP7: 357.53 | CQ7: 225.52 | CR7: 212.32 | CS7: 344.6 | CT7: 413.76 | CU7: 211.75 | CV7: 379.94 | CW7: 109.76 | CX7: 195.04 | CY7: 292.86 | CZ7: 204.42 | DA7: 410.94 | DB7: 154.98 | DC7: 100.38 | DD7: 1354.58 | DE7: 189.29 | DF7: 152.57 | DG7: 186.92 | DH7: 141.97 | DI7: 214.08 | DJ7: 1055.43 | DK7: 110.45 | DL7: 188.15 | DM7: 172.63 | DN7: 112.31 | DO7: 134.99 | DP7: 1212.02 | DQ7: 260.02 | DR7: 129.38 | DS7: 159.66 | DT7: 163.04 | DU7: 122.59 | DV7: 251.05 | DW7: 133.9 | DX7: 133.94 | DY7: 643.02 | DZ7: 142.88
A8: КРС | B8: Сельхозпредприятия | C8: АТЫРАУСКАЯ ОБЛАСТЬ | D8: 20.8 | E8: 0.8 | F8: 15.28 | G8: 1.97 | H8: 2.04 | I8: 1.32 | J8: 0.8 | K8: 1.38 | L8: 1 | M8: 0.43 | N8: 1.47 | O8: 6.26 | P8: 7.41 | Q8: 20.63 | R8: 10.49 | S8: 11.75 | T8: 16.13 | U8: 27.56 | V8: 15.8 | W8: 11.24 | X8: 15.2 | Y8: 3.5 | Z8: 5.1 | AA8: 10.18 | AB8: 7.41 | AC8: 4.52 | AD8: 6.2 | AE8: 3.28 | AF8: 9.99 | AG8: 3.44 | AH8: 9.3 | AI8: 32.91 | AJ8: 48.26 | AK8: 21.35 | AL8: 4.52 | AM8: 6.7 | AN8: 2.95 | AO8: 38.66 | AP8: 2.91 | AQ8: 23.24 | AR8: 8.43 | AS8: 2.4 | AT8: 19.8 | AU8: 0.3 | AV8: 13.88 | AW8: 1.75 | AX8: 83.62 | AY8: 19.94 | AZ8: 5.04 | BA8: 3.28 | BB8: 0.2 | BC8: 7.3 | BD8: 7.88 | BE8: 7.82 | BF8: 0.1 | BG8: - | BH8: 2.1 | BI8: 13.76 | BJ8: 1.73 | BK8: 1.95 | BL8: 1.8 | BM8: 6.49 | BN8: 7.29 | BO8: 5.7 | BP8: 10.95 | BQ8: 5.98 | BR8: 1.57 | BS8: 1.58 | BT8: 19.4 | BU8: 9.32 | BV8: 22.87 | BW8: - | BX8: 3.09 | BY8: 3.23 | BZ8: 8.92 | CA8: 2.74 | CB8: 3.85 | CC8: 2.11 | CD8: 4.54 | CE8: 1.41 | CF8: 1.69 | CG8: 8.27 | CH8: 13.06 | CI8: 20.24 | CJ8: 8.91 | CK8: 9.61 | CL8: 2.14 | CM8: 9.05 | CN8: 5.62 | CO8: 3.5 | CP8: - | CQ8: - | CR8: 2.6 | CS8: - | CT8: 5.1 | CU8: 5.7 | CV8: - | CW8: 0.06 | CX8: 1.9 | CY8: - | CZ8: 1.4 | DA8: 4.2 | DB8: 1.4 | DC8: 0.5 | DD8: 1.64 | DE8: 0.54 | DF8: - | DG8: 51.62 | DH8: 16.21 | DI8: 17.45 | DJ8: 13.52 | DK8: 25.1 | DL8: 13.7 | DM8: 16.08 | DN8: 17.35 | DO8: 41.57 | DP8: 56.59 | DQ8: 49.5 | DR8: 40.76 | DS8: 27.22 | DT8: 37.37 | DU8: 18.66 | DV8: 20.92 | DW8: 12.58 | DX8: 26.56 | DY8: 23.3 | DZ8: 17.9
A9: КРС | B9: Сельхозпредприятия | C9: ЗАПАДНО-КАЗАХСТАНСКАЯ ОБЛАСТЬ | D9: 36.38 | E9: 16.14 | F9: 148.5 | G9: 145.26 | H9: 131.27 | I9: 115.01 | J9: 60.6 | K9: 83.6 | L9: 139.05 | M9: 107.98 | N9: 86.18 | O9: 275.77 | P9: 93.81 | Q9: 204.86 | R9: 254.4 | S9: 82.89 | T9: 52.21 | U9: 57.31 | V9: 33.9 | W9: 20.69 | X9: 47.04 | Y9: 72.48 | Z9: 102.36 | AA9: 252.42 | AB9: 87.81 | AC9: 153.02 | AD9: 176.98 | AE9: 87.71 | AF9: 123.81 | AG9: 217.05 | AH9: 133.89 | AI9: 113.86 | AJ9: 86.96 | AK9: 67.89 | AL9: 188.91 | AM9: 312.2 | AN9: 155.96 | AO9: 131.87 | AP9: 155.17 | AQ9: 183.75 | AR9: 131.9 | AS9: 220.58 | AT9: 117.82 | AU9: 77.65 | AV9: 271.51 | AW9: 169.24 | AX9: 230.18 | AY9: 256.49 | AZ9: 126.91 | BA9: 104.17 | BB9: 95.67 | BC9: 94.31 | BD9: 75.93 | BE9: 248.36 | BF9: 150.05 | BG9: 104.48 | BH9: 396.66 | BI9: 194.05 | BJ9: 288.29 | BK9: 375.54 | BL9: 208.8 | BM9: 151.24 | BN9: 137.98 | BO9: 108.61 | BP9: 142.46 | BQ9: 302.43 | BR9: 70.79 | BS9: 120.1 | BT9: 288.51 | BU9: 342.18 | BV9: 290.2 | BW9: 633.29 | BX9: 135.28 | BY9: 200.06 | BZ9: 271.74 | CA9: 621.21 | CB9: 617.36 | CC9: 350.28 | CD9: 87.77 | CE9: 121.58 | CF9: 194.95 | CG9: 156.73 | CH9: 267.81 | CI9: 585.09 | CJ9: 152.48 | CK9: 368.91 | CL9: 202.78 | CM9: 439.32 | CN9: 284.58 | CO9: 1207.68 | CP9: 224.12 | CQ9: 134.71 | CR9: 265.6 | CS9: 299.54 | CT9: 504.28 | CU9: 406.81 | CV9: 560.11 | CW9: 266.3 | CX9: 327.79 | CY9: 372.54 | CZ9: 238.97 | DA9: 585.79 | DB9: 444.99 | DC9: 519.78 | DD9: 679.56 | DE9: 630.95 | DF9: 380.4 | DG9: 457.86 | DH9: 486.18 | DI9: 222.78 | DJ9: 333.47 | DK9: 438.04 | DL9: 378.2 | DM9: 585.85 | DN9: 607.34 | DO9: 944.69 | DP9: 517.31 | DQ9: 622.35 | DR9: 478.05 | DS9: 964.38 | DT9: 188.16 | DU9: 166.92 | DV9: 445.93 | DW9: 303.29 | DX9: 246.96 | DY9: 645.76 | DZ9: 1126.35
A10: КРС | B10: Сельхозпредприятия | C10: ЖАМБЫЛСКАЯ ОБЛАСТЬ | D10: 11.35 | E10: 52.62 | F10: 24.71 | G10: 76.56 | H10: 106.33 | I10: 23.48 | J10: 128.48 | K10: 270.8 | L10: 30.13 | M10: 19.1 | N10: 32.88 | O10: 44.2 | P10: 16.08 | Q10: 475.59 | R10: 29.41 | S10: 310.03 | T10: 365.45 | U10: 32.66 | V10: 23.9 | W10: 22.9 | X10: 30.94 | Y10: 54.8 | Z10: 64.1 | AA10: 910.5 | AB10: 16.08 | AC10: 335.1 | AD10: 194.9 | AE10: 464.6 | AF10: 119.09 | AG10: 242.96 | AH10: 531.87 | AI10: 1150.32 | AJ10: 40.43 | AK10: 32.15 | AL10: 328.86 | AM10: 780.76 | AN10: 436.41 | AO10: 39.11 | AP10: 1024.84 | AQ10: 876.02 | AR10: 845.38 | AS10: 843.11 | AT10: 461.87 | AU10: 1072.21 | AV10: 1831.9 | AW10: 352.13 | AX10: 542.21 | AY10: 2062.63 | AZ10: 541.83 | BA10: 448.71 | BB10: 972.35 | BC10: 530.18 | BD10: 404.28 | BE10: 1844.94 | BF10: 308.46 | BG10: 1231.96 | BH10: 1682.59 | BI10: 637.14 | BJ10: 543.51 | BK10: 1728.36 | BL10: 2042.34 | BM10: 114.99 | BN10: 296.28 | BO10: 239.43 | BP10: 282.82 | BQ10: 694.06 | BR10: 37.06 | BS10: 1190.01 | BT10: 771.9 | BU10: 384.79 | BV10: 96.09 | BW10: 5995.41 | BX10: 1891.17 | BY10: 84.23 | BZ10: 1040.02 | CA10: 175.75 | CB10: 240.53 | CC10: 1529.83 | CD10: 71.09 | CE10: 721.52 | CF10: 2466.15 | CG10: 1049.29 | CH10: 791.7 | CI10: 5273.3 | CJ10: 290.29 | CK10: 371.16 | CL10: 1393.47 | CM10: 33.66 | CN10: 87.63 | CO10: 1066.24 | CP10: 12.23 | CQ10: 134.58 | CR10: 997.34 | CS10: 394.67 | CT10: 359.43 | CU10: 1708.7 | CV10: 136.63 | CW10: 44.93 | CX10: 1223.68 | CY10: 54.84 | CZ10: 140.49 | DA10: 817.71 | DB10: 9.3 | DC10: 13.4 | DD10: 58.06 | DE10: 77.19 | DF10: 98.82 | DG10: 25.2 | DH10: 174.82 | DI10: 122.55 | DJ10: 1474.62 | DK10: 96.11 | DL10: 187.05 | DM10: 148.03 | DN10: 102.68 | DO10: 33.38 | DP10: 6.29 | DQ10: 16.55 | DR10: 18.3 | DS10: 30.96 | DT10: 38.12 | DU10: 18.6 | DV10: 11.9 | DW10: 20.04 | DX10: 312.1 | DY10: 2099.37 | DZ10: 12.31
A11: КРС | B11: Сельхозпредприятия | C11: КАРАГАНДИНСКАЯ ОБЛАСТЬ | D11: 40.29 | E11: 47.49 | F11: 16.23 | G11: 39.16 | H11: 37.99 | I11: 33.46 | J11: 25.4 | K11: 31.9 | L11: 77.93 | M11: 30.58 | N11: 24.93 | O11: 37.44 | P11: 32.49 | Q11: 10.82 | R11: 40.55 | S11: 38.06 | T11: 28.86 | U11: 83.94 | V11: 31.25 | W11: 54.59 | X11: 85.77 | Y11: 24.29 | Z11: 72.41 | AA11: 91.5 | AB11: 32.49 | AC11: 47.11 | AD11: 42.94 | AE11: 78.41 | AF11: 115.8 | AG11: 101.38 | AH11: 22.44 | AI11: 80.06 | AJ11: 83.36 | AK11: 145.24 | AL11: 82.44 | AM11: 82.15 | AN11: 5.07 | AO11: 43.84 | AP11: 39.76 | AQ11: 24.68 | AR11: 82.12 | AS11: 53.05 | AT11: 37.93 | AU11: 46.48 | AV11: 68.56 | AW11: 15.85 | AX11: 44.14 | AY11: 174.4 | AZ11: 16.87 | BA11: 106.38 | BB11: 180.45 | BC11: 133.89 | BD11: 170.19 | BE11: 238.98 | BF11: 102.7 | BG11: 305.21 | BH11: 419.21 | BI11: 138.87 | BJ11: 193.71 | BK11: 139.51 | BL11: 328.37 | BM11: 86.42 | BN11: 351.35 | BO11: 70.14 | BP11: 952.68 | BQ11: 715.18 | BR11: 164.18 | BS11: 269.7 | BT11: 109.17 | BU11: 647.51 | BV11: 603.22 | BW11: 484.61 | BX11: 542.91 | BY11: 493.85 | BZ11: 320.3 | CA11: 448.12 | CB11: 460.57 | CC11: 988.61 | CD11: 712.53 | CE11: 693.67 | CF11: 895.13 | CG11: 1273.47 | CH11: 471.63 | CI11: 737.66 | CJ11: 1003.01 | CK11: 311.82 | CL11: 1384.38 | CM11: 343.76 | CN11: 236.06 | CO11: 104.21 | CP11: 155.95 | CQ11: 60.88 | CR11: 270.58 | CS11: 646.19 | CT11: 113.16 | CU11: 303.28 | CV11: 244.88 | CW11: 227.98 | CX11: 215.2 | CY11: 103.78 | CZ11: 188.89 | DA11: 148.8 | DB11: 90.28 | DC11: 162.8 | DD11: 206.27 | DE11: 260.49 | DF11: 242.88 | DG11: 250.05 | DH11: 126.06 | DI11: 155.18 | DJ11: 91.43 | DK11: 242.05 | DL11: 189.97 | DM11: 167.94 | DN11: 87.91 | DO11: 103.4 | DP11: 191.9 | DQ11: 116.85 | DR11: 101.7 | DS11: 153.63 | DT11: 107.62 | DU11: 65.41 | DV11: 110.84 | DW11: 288.45 | DX11: 127.81 | DY11: 125.36 | DZ11: 79.87
A12: КРС | B12: Сельхозпредприятия | C12: КОСТАНАЙСКАЯ ОБЛАСТЬ | D12: 817.94 | E12: 781.68 | F12: 1025.47 | G12: 1792.38 | H12: 2083.39 | I12: 3322.77 | J12: 978.73 | K12: 838.09 | L12: 899.01 | M12: 1060.38 | N12: 885.49 | O12: 831.85 | P12: 838 | Q12: 740.93 | R12: 876.01 | S12: 1083.93 | T12: 1019.43 | U12: 3257.55 | V12: 1015.65 | W12: 934.94 | X12: 1080.12 | Y12: 1093.06 | Z12: 1287.79 | AA12: 2205.76 | AB12: 802.38 | AC12: 952.64 | AD12: 1157.22 | AE12: 1192.33 | AF12: 1669.27 | AG12: 4498.26 | AH12: 970.85 | AI12: 1222.57 | AJ12: 1299.34 | AK12: 1034.82 | AL12: 1174.66 | AM12: 858.06 | AN12: 1393.16 | AO12: 895.8 | AP12: 1244.7 | AQ12: 1447.37 | AR12: 1670.15 | AS12: 5149.34 | AT12: 1077.28 | AU12: 960.89 | AV12: 1827.93 | AW12: 1074.91 | AX12: 1632.42 | AY12: 1061.72 | AZ12: 1107.37 | BA12: 1135.43 | BB12: 1327.85 | BC12: 1796.84 | BD12: 1704.62 | BE12: 4020.51 | BF12: 1438.87 | BG12: 897.65 | BH12: 908.52 | BI12: 946.92 | BJ12: 1068.18 | BK12: 1341.32 | BL12: 1157.73 | BM12: 1242.94 | BN12: 1467.15 | BO12: 2470.35 | BP12: 1841.89 | BQ12: 3526.6 | BR12: 1979.69 | BS12: 1571.54 | BT12: 2240.05 | BU12: 1595.89 | BV12: 2066.84 | BW12: 1033.47 | BX12: 1829.51 | BY12: 1685.36 | BZ12: 1641.54 | CA12: 3008.28 | CB12: 2051.72 | CC12: 3343.7 | CD12: 2618.22 | CE12: 1226.29 | CF12: 1693.72 | CG12: 1235.14 | CH12: 1341.27 | CI12: 1584.67 | CJ12: 1584.88 | CK12: 797.82 | CL12: 1301.96 | CM12: 1342.3 | CN12: 1667.23 | CO12: 3263.81 | CP12: 1211.14 | CQ12: 1056.05 | CR12: 940.87 | CS12: 832.46 | CT12: 1277.4 | CU12: 1336.82 | CV12: 1661.98 | CW12: 1627.84 | CX12: 1111.26 | CY12: 1344.04 | CZ12: 1241.39 | DA12: 1300.84 | DB12: 1105.81 | DC12: 910.57 | DD12: 1125.24 | DE12: 1227.25 | DF12: 1301.43 | DG12: 1261.47 | DH12: 1150.38 | DI12: 1287.7 | DJ12: 1382.07 | DK12: 1446.57 | DL12: 1251.74 | DM12: 6621.92 | DN12: 1607.87 | DO12: 950.82 | DP12: 1441.72 | DQ12: 1435.26 | DR12: 1167.13 | DS12: 1385.27 | DT12: 1028.42 | DU12: 889.12 | DV12: 1041.43 | DW12: 1276.99 | DX12: 961.53 | DY12: 1911.32 | DZ12: 1266.17
A13: КРС | B13: Сельхозпредприятия | C13: КЫЗЫЛОРДИНСКАЯ ОБЛАСТЬ | D13: 9.7 | E13: 15.3 | F13: 21.82 | G13: 13.13 | H13: 6.71 | I13: 8.39 | J13: 10.09 | K13: 11.92 | L13: 2.83 | M13: 6.97 | N13: 19.56 | O13: 29.11 | P13: 38.57 | Q13: 51.26 | R13: 32.6 | S13: 20.65 | T13: 37.15 | U13: 36.43 | V13: 66.24 | W13: 39.69 | X13: 2.55 | Y13: 5.79 | Z13: 70.36 | AA13: 30.24 | AB13: 38.57 | AC13: 21.7 | AD13: 17.81 | AE13: 26.37 | AF13: 3.38 | AG13: 38.11 | AH13: 51.17 | AI13: 61.91 | AJ13: 53.46 | AK13: 33.07 | AL13: 29.39 | AM13: 54.1 | AN13: 65.32 | AO13: 142.19 | AP13: 58.72 | AQ13: 48.72 | AR13: 35.28 | AS13: 26.96 | AT13: 38.28 | AU13: 87.59 | AV13: 52.81 | AW13: 37.98 | AX13: 65.91 | AY13: 170.68 | AZ13: 28.57 | BA13: 65.99 | BB13: 80.61 | BC13: 10.5 | BD13: 175.95 | BE13: 81.66 | BF13: 89.71 | BG13: 96.17 | BH13: 166.27 | BI13: 66.62 | BJ13: 118.68 | BK13: 255.65 | BL13: 133.48 | BM13: 84.45 | BN13: 30.21 | BO13: 175.04 | BP13: 100.7 | BQ13: 108.92 | BR13: 32.74 | BS13: 41.8 | BT13: 55.64 | BU13: 79.1 | BV13: 108.48 | BW13: 87.39 | BX13: 42.77 | BY13: 75.82 | BZ13: 42.22 | CA13: 143.2 | CB13: 91.79 | CC13: 116.17 | CD13: 38.34 | CE13: 22.73 | CF13: 8.27 | CG13: 113.74 | CH13: 85.71 | CI13: 138.19 | CJ13: 58.05 | CK13: 67.25 | CL13: 64.33 | CM13: 148.01 | CN13: 87.8 | CO13: 121.7 | CP13: 45.17 | CQ13: 53.29 | CR13: 30.73 | CS13: 78.78 | CT13: 112.24 | CU13: 193.63 | CV13: 62.35 | CW13: 65.44 | CX13: 51.9 | CY13: 141.42 | CZ13: 81 | DA13: 120.39 | DB13: 27.99 | DC13: 49.09 | DD13: 62.45 | DE13: 77.84 | DF13: 82.33 | DG13: 117.03 | DH13: 117.25 | DI13: 75.01 | DJ13: 51.07 | DK13: 118.23 | DL13: 104.68 | DM13: 137.22 | DN13: 43.34 | DO13: 71.07 | DP13: 55.35 | DQ13: 79.58 | DR13: 41.26 | DS13: 110.81 | DT13: 24.44 | DU13: 77.94 | DV13: 40.51 | DW13: 180.28 | DX13: 84.18 | DY13: 141.85 | DZ13: 62.35
A14: КРС | B14: Сельхозпредприятия | C14: МАНГИСТАУСКАЯ ОБЛАСТЬ | D14: - | E14: - | F14: - | G14: - | H14: - | I14: - | J14: - | K14: - | L14: - | M14: - | N14: - | O14: - | P14: - | Q14: - | R14: 4.83 | S14: - | T14: - | U14: - | V14: - | W14: - | X14: - | Y14: - | Z14: - | AA14: - | AB14: - | AC14: - | AD14: 2 | AE14: - | AF14: - | AG14: - | AH14: - | AI14: - | AJ14: - | AK14: - | AL14: 2.07 | AM14: - | AN14: - | AO14: - | AP14: 0.62 | AQ14: - | AR14: - | AS14: 1.78 | AT14: 0.3 | AU14: - | AV14: 0.3 | AW14: 0.6 | AX14: - | AY14: - | AZ14: - | BA14: - | BB14: - | BC14: - | BD14: 0.6 | BE14: 0.9 | BF14: 3.28 | BG14: 1.66 | BH14: 0.58 | BI14: 8.84 | BJ14: - | BK14: - | BL14: 9 | BM14: 2.8 | BN14: 5.6 | BQ14: 7.2 | BR14: 2.32 | BS14: 0.28 | BT14: 3.93 | BU14: 1.95 | BV14: 4.78 | BW14: 0.35 | BX14: 3.36 | BY14: 5.8 | BZ14: 2.1 | CA14: 0.28 | CB14: 2.8 | CC14: 2.8 | CD14: 2.8 | CE14: 2.8 | CF14: 0.63 | CG14: 2.8 | CH14: 2.8 | CI14: 1.47 | CJ14: 1.12 | CK14: 1.47 | CL14: 13.42 | CM14: 1.12 | CN14: 1.12 | CO14: 1.7 | CP14: 1.12 | CQ14: 1.12 | CR14: 1.12 | CS14: 1.12 | CT14: 1.96 | CU14: 1.12 | CV14: 1.4 | CW14: 1.12 | CX14: 1.4 | CY14: 1.42 | CZ14: 1.12 | DA14: 2.62 | DB14: 1.12 | DC14: 1.97 | DD14: 1.12 | DE14: 1.88 | DF14: 1.12 | DG14: 1.12 | DH14: 1.12 | DI14: 2.8 | DJ14: 1.68 | DK14: 1.68 | DL14: 151.68 | DM14: 1.68 | DN14: 1.68 | DO14: 1.68 | DP14: 10.14 | DQ14: 1.68 | DR14: 2.28 | DS14: 2.08 | DT14: 2.24 | DU14: 2.08 | DV14: 6.05 | DW14: 0.28 | DX14: 0.3 | DY14: 0.4 | DZ14: 0.56
A15: КРС | B15: Сельхозпредприятия | C15: ЮЖНО-КАЗАХСТАНСКАЯ ОБЛАСТЬ | D15: 434.41 | E15: 519.56 | F15: 344.48 | G15: 626.53 | H15: 331.32 | I15: 464.68 | J15: 145.87 | K15: 221.28 | L15: 254.04 | M15: 312.79 | N15: 177.3 | O15: 863.13 | P15: 392.29 | Q15: 233.13 | R15: 354.3 | S15: 398 | T15: 226.54 | U15: 619.38 | V15: 240.88 | W15: 539.7 | X15: 338.12 | Y15: 286.87 | Z15: 579.32 | AA15: 1022.92 | AB15: 372.59 | AC15: 968.05 | AD15: 1500.42 | AE15: 993.48 | AF15: 377.09 | AG15: 1606.58 | AH15: 775.97 | AI15: 521.21 | AJ15: 895.63 | AK15: 909.82 | AL15: 1044.65 | AM15: 2417.82 | AN15: 355.56 | AO15: 249.32 | AP15: 1663.52 | AQ15: 2122.05 | AR15: 1381.2 | AS15: - | AT15: - | AU15: - | AV15: - | AW15: - | AX15: - | AY15: - | AZ15: - | BA15: - | BB15: - | BC15: - | BD15: - | BE15: - | BF15: - | BG15: - | BH15: - | BI15: - | BJ15: - | BK15: - | BL15: - | BM15: - | BN15: - | BO15: - | BP15: - | BQ15: - | BR15: - | BS15: - | BT15: - | BU15: - | BV15: - | BW15: - | BX15: - | BY15: - | BZ15: - | CA15: - | CB15: - | CC15: - | CD15: - | CE15: - | CF15: - | CG15: - | CH15: - | CI15: - | CJ15: - | CK15: - | CL15: - | CM15: - | CN15: - | CO15: - | CP15: - | CQ15: - | CR15: - | CS15: - | CT15: - | CU15: - | CV15: - | CW15: - | CX15: - | CY15: - | CZ15: - | DA15: - | DB15: - | DC15: - | DD15: - | DE15: - | DF15: - | DG15: - | DH15: - | DI15: - | DJ15: - | DK15: - | DL15: - | DM15: - | DN15: - | DO15: - | DP15: - | DQ15: - | DR15: - | DS15: - | DT15: - | DU15: - | DV15: - | DW15: - | DX15: - | DY15: - | DZ15: -
A16: КРС | B16: Сельхозпредприятия | C16: ПАВЛОДАРСКАЯ ОБЛАСТЬ | D16: 402.8 | E16: 408.76 | F16: 424.88 | G16: 487.96 | H16: 440.03 | I16: 518.17 | J16: 770.65 | K16: 842.02 | L16: 776.12 | M16: 345.44 | N16: 282.37 | O16: 790.16 | P16: 339.93 | Q16: 269.26 | R16: 499.2 | S16: 576.61 | T16: 368.66 | U16: 871.09 | V16: 646.83 | W16: 508.52 | X16: 973.35 | Y16: 232.75 | Z16: 631.38 | AA16: 638.59 | AB16: 338.93 | AC16: 157.95 | AD16: 158.36 | AE16: 388.06 | AF16: 254.5 | AG16: 416.09 | AH16: 282.37 | AI16: 289.29 | AJ16: 345.06 | AK16: 773.57 | AL16: 824.63 | AM16: 992.74 | AN16: 393.47 | AO16: 265.74 | AP16: 391.62 | AQ16: 201.14 | AR16: 433.72 | AS16: 753.74 | AT16: 294.93 | AU16: 325.06 | AV16: 786.56 | AW16: 775.64 | AX16: 733.53 | AY16: 1622.78 | AZ16: 211.95 | BA16: 441.29 | BB16: 533.58 | BC16: 321.87 | BD16: 706.05 | BE16: 534.05 | BF16: 881.45 | BG16: 496.49 | BH16: 355.15 | BI16: 293.76 | BJ16: 1059.62 | BK16: 1544.28 | BL16: 355.19 | BM16: 243.26 | BN16: 612.79 | BO16: 277.53 | BP16: 578.97 | BQ16: 456.65 | BR16: 1014.16 | BS16: 716.05 | BT16: 636.9 | BU16: 885.98 | BV16: 818.73 | BW16: 2188.29 | BX16: 398.5 | BY16: 403.99 | BZ16: 870.2 | CA16: 923.39 | CB16: 740.49 | CC16: 607.08 | CD16: 959.6 | CE16: 917.49 | CF16: 731.16 | CG16: 545.36 | CH16: 887.62 | CI16: 1810.01 | CJ16: 271.89 | CK16: 2370.49 | CL16: 962.21 | CM16: 1007.96 | CN16: 517.81 | CO16: 687.08 | CP16: 678.43 | CQ16: 598.33 | CR16: 883.29 | CS16: 587.76 | CT16: 740.83 | CU16: 1700.91 | CV16: 549.21 | CW16: 660.73 | CX16: 915.12 | CY16: 768.14 | CZ16: 869.2 | DA16: 1089.89 | DB16: 1072.2 | DC16: 1236.93 | DD16: 2337.08 | DE16: 996.25 | DF16: 1918.87 | DG16: 3755.36 | DH16: 1112.22 | DI16: 961.47 | DJ16: 409.36 | DK16: 983.53 | DL16: 1019.96 | DM16: 1508.75 | DN16: 2012.29 | DO16: 2007.43 | DP16: 1848.26 | DQ16: 1064.54 | DR16: 1310.19 | DS16: 1556.47 | DT16: 898.4 | DU16: 548.47 | DV16: 654.6 | DW16: 836.97 | DX16: 515.48 | DY16: 844.05 | DZ16: 1379.57
A17: КРС | B17: Сельхозпредприятия | C17: СЕВЕРО-КАЗАХСТАНСКАЯ ОБЛАСТЬ | D17: 218.07 | E17: 303.24 | F17: 267.73 | G17: 280.28 | H17: 341.49 | I17: 353.54 | J17: 372.24 | K17: 234.7 | L17: 430.49 | M17: 387.3 | N17: 358.04 | O17: 1011.06 | P17: 341.98 | Q17: 370.56 | R17: 416.25 | S17: 504.44 | T17: 383.02 | U17: 499.68 | V17: 480.27 | W17: 324.19 | X17: 468.37 | Y17: 297.97 | Z17: 527.3 | AA17: 884.3 | AB17: 341.87 | AC17: 316.37 | AD17: 719.58 | AE17: 414.61 | AF17: 460.09 | AG17: 427.32 | AH17: 411.27 | AI17: 389.62 | AJ17: 635.97 | AK17: 424.33 | AL17: 366.3 | AM17: 912.52 | AN17: 494.92 | AO17: 471.05 | AP17: 470.98 | AQ17: 483.59 | AR17: 432.93 | AS17: 532.49 | AT17: 538.69 | AU17: 414.53 | AV17: 831.98 | AW17: 723.19 | AX17: 564.36 | AY17: 626.21 | AZ17: 1012.05 | BA17: 468.35 | BB17: 588.4 | BC17: 503.16 | BD17: 541.03 | BE17: 319.02 | BF17: 557.32 | BG17: 381.62 | BH17: 764.64 | BI17: 686.16 | BJ17: 592.07 | BK17: 480.3 | BL17: 558.71 | BM17: 615.82 | BN17: 529.01 | BO17: 454.54 | BP17: 634.85 | BQ17: 555.75 | BR17: 527.89 | BS17: 465.84 | BT17: 478.24 | BU17: 533.33 | BV17: 538.29 | BW17: 889 | BX17: 591.26 | BY17: 550.55 | BZ17: 507.42 | CA17: 459.87 | CB17: 528.94 | CC17: 1418.29 | CD17: 479.77 | CE17: 596.23 | CF17: 648.17 | CG17: 504.34 | CH17: 664.41 | CI17: 843.92 | CJ17: 768.53 | CK17: 560.8 | CL17: 442.98 | CM17: 679.06 | CN17: 602.34 | CO17: 754.7 | CP17: 672.36 | CQ17: 933.81 | CR17: 697.62 | CS17: 574.1 | CT17: 527.77 | CU17: 588.54 | CV17: 984.58 | CW17: 714.7 | CX17: 491.86 | CY17: 637.19 | CZ17: 805.11 | DA17: 558.52 | DB17: 395.9 | DC17: 630.21 | DD17: 845.73 | DE17: 730.06 | DF17: 711.61 | DG17: 847.3 | DH17: 596.12 | DI17: 989.29 | DJ17: 642.24 | DK17: 554.03 | DL17: 601.03 | DM17: 641.57 | DN17: 547.02 | DO17: 781.65 | DP17: 846.54 | DQ17: 888.54 | DR17: 667.25 | DS17: 620.08 | DT17: 707.37 | DU17: 718.89 | DV17: 1023.57 | DW17: 489.57 | DX17: 569.49 | DY17: 643.07 | DZ17: 539.46
A18: КРС | B18: Сельхозпредприятия | C18: ВОСТОЧНО-КАЗАХСТАНСКАЯ ОБЛАСТЬ | D18: 159.16 | E18: 156.45 | F18: 148.85 | G18: 163.8 | H18: 144.58 | I18: 239.64 | J18: 114.96 | K18: 104.63 | L18: 122.44 | M18: 104.61 | N18: 206.82 | O18: 219.19 | P18: 204.36 | Q18: 177.03 | R18: 172.56 | S18: 211.78 | T18: 141.65 | U18: 134.04 | V18: 141.97 | W18: 91.93 | X18: 283.74 | Y18: 147.68 | Z18: 217.08 | AA18: 273.54 | AB18: 203.81 | AC18: 128.84 | AD18: 199.39 | AE18: 186.04 | AF18: 184.49 | AG18: 128.07 | AH18: 117.95 | AI18: 111.19 | AJ18: 172.05 | AK18: 221.54 | AL18: 284.03 | AM18: 227.43 | AN18: 248.21 | AO18: 159.57 | AP18: 215.56 | AQ18: 245.75 | AR18: 302.96 | AS18: 199.41 | AT18: 138.97 | AU18: 164.26 | AV18: 571.97 | AW18: 174.7 | AX18: 284.69 | AY18: 313.99 | AZ18: 163.81 | BA18: 237.89 | BB18: 266.05 | BC18: 184.69 | BD18: 199.97 | BE18: 199.44 | BF18: 89.93 | BG18: 208.9 | BH18: 120.67 | BI18: 139.32 | BJ18: 113.26 | BK18: 212.78 | BL18: 151.44 | BM18: 168.09 | BN18: 160.47 | BO18: 193.65 | BP18: 198.09 | BQ18: 392.1 | BR18: 281.28 | BS18: 240.62 | BT18: 327.88 | BU18: 194.5 | BV18: 303.64 | BW18: 446.17 | BX18: 208.81 | BY18: 174.93 | BZ18: 289.09 | CA18: 194.13 | CB18: 216.21 | CC18: 242.64 | CD18: 238.61 | CE18: 214.74 | CF18: 213.25 | CG18: 225.47 | CH18: 214.58 | CI18: 364.48 | CJ18: 333.66 | CK18: 165.1 | CL18: 164.16 | CM18: 254.36 | CN18: 166.72 | CO18: 87.6 | CP18: 112.23 | CQ18: 152.53 | CR18: 164.24 | CS18: 110.24 | CT18: 182.39 | CU18: 146.32 | CV18: 142.15 | CW18: 153.67 | CX18: 132.31 | CY18: 280.38 | CZ18: 288.23 | DA18: 180.75 | DB18: 102.82 | DC18: 101.26 | DD18: 136.41 | DE18: 124.06 | DF18: 119.46 | DG18: 226.39 | DH18: 307.86 | DI18: 178.11 | DJ18: 104.42 | DK18: 97.76 | DL18: 255.84 | DM18: 135.62 | DN18: 90.49 | DO18: 92.79 | DP18: 157.31 | DQ18: 135.47 | DR18: 105.11 | DS18: 140.81 | DT18: 82.15 | DU18: 123.63 | DV18: 99.82 | DW18: 88.96 | DX18: 94.12 | DY18: 73.46 | DZ18: 76.64
A19: КРС | B19: Сельхозпредприятия | C19: ГАСТАНА | D19: 2.6 | E19: 18.7 | F19: 6.5 | G19: 11.8 | H19: 11.4 | I19: 12.2 | J19: 1.7 | K19: 2.77 | L19: 2.63 | M19: 3 | N19: 3.5 | O19: 2.9 | P19: 2.5 | Q19: 1.74 | R19: 2.01 | S19: 2.47 | T19: 2.67 | U19: 0.85 | V19: 1.22 | X19: 5.3 | AA19: 1.4 | AB19: 2.5 | AD19: 2.4 | AE19: 3.84 | AF19: 1.79 | AG19: 2.92 | AH19: 3.33 | AI19: 4.96 | AJ19: 8.33 | AK19: 7.56 | AL19: 7.99 | AM19: 3.95 | AN19: 5.07 | AO19: 0.51 | AP19: 1.81 | AQ19: 0.8 | AS19: 3.39 | AT19: 1.83 | AU19: 2.44 | AV19: 1.27 | AW19: 1.14 | AX19: 2.3 | AY19: 0.84 | AZ19: 1.24 | BA19: 1.79 | BB19: 0.62 | BC19: 0.96 | BD19: 0.59 | BE19: - | BF19: - | BG19: - | BH19: - | BI19: - | BJ19: - | BK19: 2.5 | BL19: - | BM19: - | BN19: 0.12 | BO19: - | BP19: - | BQ19: 0.2 | BR19: - | BS19: - | BT19: - | BU19: - | BV19: - | BW19: - | BX19: - | BY19: - | BZ19: - | CA19: - | CB19: - | CC19: - | CD19: - | CE19: - | CF19: - | CG19: - | CH19: - | CI19: - | CJ19: - | CK19: - | CL19: - | CM19: - | CN19: - | CO19: - | CP19: - | CQ19: - | CR19: - | CS19: 0.3 | CT19: 1.17 | CU19: 1.1 | CV19: - | CW19: - | CX19: - | CY19: - | CZ19: - | DA19: - | DB19: - | DC19: - | DD19: - | DE19: - | DF19: - | DG19: - | DH19: - | DI19: - | DJ19: - | DK19: - | DL19: - | DM19: - | DN19: - | DO19: - | DP19: - | DQ19: - | DR19: - | DS19: - | DT19: - | DU19: - | DV19: - | DW19: - | DX19: - | DY19: - | DZ19: -
A20: КРС | B20: Сельхозпредприятия | C20: ГАЛМАТЫ
A21: КРС | B21: Сельхозпредприятия | C21: ГШЫМКЕНТ | D21: - | E21: - | F21: - | G21: - | H21: - | I21: - | J21: - | K21: - | L21: - | M21: - | N21: - | O21: - | P21: - | Q21: - | R21: - | S21: - | T21: - | U21: - | V21: - | W21: - | X21: - | Y21: - | Z21: - | AA21: - | AB21: - | AC21: - | AD21: - | AE21: - | AF21: - | AG21: - | AH21: - | AI21: - | AJ21: - | AK21: - | AL21: - | AM21: - | AN21: - | AO21: - | AP21: - | AQ21: - | AR21: - | AS21: 905.63 | AT21: 583.22 | AU21: 5.12 | AV21: 67.68 | AW21: 3.24 | AX21: 21.83 | AY21: 50.41 | AZ21: 12.76 | BA21: 5.55 | BB21: 7.6 | BC21: 1205.5 | BD21: 1215.1 | BE21: 1555.6 | BF21: 473.18 | BG21: 519.6 | BH21: 128.42 | BI21: 310.47 | BJ21: 307.5 | BK21: 190.59 | BL21: 8.63 | BM21: 7.76 | BN21: 6.61 | BO21: 746.92 | BP21: 1114.42 | BQ21: 1810.28 | BR21: 350.53 | BS21: 571.21 | BT21: 165.95 | BU21: 551.41 | BV21: 243.51 | BW21: 185.68 | BX21: 64.77 | BY21: 117.88 | BZ21: 130.78 | CA21: 537.19 | CB21: 1187.86 | CC21: 2161.93 | CD21: 405.63 | CE21: 462.42 | CF21: 365.87 | CG21: 410.02 | CH21: 404.36 | CI21: 627.58 | CJ21: 101 | CK21: 255.3 | CL21: 213.45 | CM21: 353.3 | CN21: 55.9 | CP21: 5.1 | CQ21: 0.61 | CR21: 35.3 | CS21: 4.44 | CT21: 4.14 | CU21: 4.84 | CV21: 57.54 | CW21: 3.72 | CX21: 140.87 | CY21: 103.29 | CZ21: 5.55 | DA21: 23.4 | DB21: 46.87 | DC21: 23.69 | DD21: 76.4 | DE21: 1283.7 | DF21: 180.08 | DG21: 53.02 | DH21: 174.25 | DI21: 73.24 | DJ21: 119.83 | DK21: 104.42 | DL21: 6.12 | DM21: 16.03 | DN21: 9.76 | DO21: 12.12 | DP21: 12.32 | DQ21: 159.15 | DR21: 245.15 | DS21: 115.84 | DT21: 70.31 | DU21: 134.77 | DV21: 1.79 | DW21: - | DX21: 0.25 | DY21: - | DZ21: -
A22: КРС | B22: Сельхозпредприятия | C22: ТУРКЕСТАНСКАЯ ОБЛАСТЬ | D22: - | E22: - | F22: - | G22: - | H22: - | I22: - | J22: - | K22: - | L22: - | M22: - | N22: - | O22: - | P22: - | Q22: - | R22: - | S22: - | T22: - | U22: - | V22: - | W22: - | X22: - | Y22: - | Z22: - | AA22: - | AB22: - | AC22: - | AD22: - | AE22: - | AF22: - | AG22: - | AH22: - | AI22: - | AJ22: - | AK22: - | AL22: - | AM22: - | AN22: - | AO22: - | AP22: - | AQ22: - | AR22: - | AS22: 2793.3 | AT22: 1730.94 | AU22: 1152.82 | AV22: 566.87 | AW22: 455.01 | AX22: 753.18 | AY22: 983.43 | AZ22: 92.25 | BA22: 95.34 | BB22: 1414.18 | BC22: 241.98 | BD22: 411.56 | BE22: 3765.31 | BF22: 636.73 | BG22: 206.89 | BH22: 578.93 | BI22: 4854.42 | BJ22: 1504.57 | BK22: 2283.82 | BL22: 210.03 | BM22: 112.97 | BN22: 1923.87 | BO22: 247.72 | BP22: 133.29 | BQ22: 3484.21 | BR22: 301.36 | BS22: 1052.79 | BT22: 1152.52 | BU22: 4039.13 | BV22: 2950.09 | BW22: 1758.42 | BX22: 445.61 | BY22: 608.19 | BZ22: 400.46 | CA22: 1158.7 | CB22: 955.62 | CC22: 688.12 | CD22: 519.62 | CE22: 5463.34 | CF22: 1411.73 | CG22: 3026.9 | CH22: 2180.12 | CI22: 3163.36 | CJ22: 586.33 | CK22: 818.11 | CL22: 1473.6 | CM22: 1226.81 | CN22: 1090.08 | CO22: 1092.42 | CP22: 1065.41 | CQ22: 4968.52 | CR22: 2037.66 | CS22: 3958.6 | CT22: 1838.15 | CU22: 2672.82 | CV22: 646.89 | CW22: 627.55 | CX22: 849.66 | CY22: 3206.97 | CZ22: 1558.11 | DA22: 1228.01 | DB22: 1290.43 | DC22: 5666.1 | DD22: 4217.24 | DE22: 1004.76 | DF22: 936.44 | DG22: 3805.03 | DH22: 601.37 | DI22: 5917.21 | DJ22: 1366.07 | DK22: 4009.21 | DL22: 1575.56 | DM22: 10529.94 | DN22: 1593.86 | DO22: 4331.39 | DP22: 8049.47 | DQ22: 2910.8 | DR22: 2821.28 | DS22: 13033.74 | DT22: 1904.86 | DU22: 1883.04 | DV22: 1553.92 | DW22: 796.6 | DX22: 1674.08 | DY22: 3205.86 | DZ22: 3120.09
A23: КРС | B23: Сельхозпредприятия | C23: ОБЛАСТЬ ЖЕТІСУ | D23: - | E23: - | F23: - | G23: - | H23: - | I23: - | J23: - | K23: - | L23: - | M23: - | N23: - | O23: - | P23: - | Q23: - | R23: - | S23: - | T23: - | U23: - | V23: - | W23: - | X23: - | Y23: - | Z23: - | AA23: - | AB23: - | AC23: - | AD23: - | AE23: - | AF23: - | AG23: - | AH23: - | AI23: - | AJ23: - | AK23: - | AL23: - | AM23: - | AN23: - | AO23: - | AP23: - | AQ23: - | AR23: - | AS23: - | AT23: - | AU23: - | AV23: - | AW23: - | AX23: - | AY23: - | AZ23: - | BA23: - | BB23: - | BC23: - | BD23: - | BE23: - | BF23: - | BG23: - | BH23: - | BI23: - | BJ23: - | BK23: - | BL23: - | BM23: - | BN23: - | BO23: - | BP23: - | BQ23: - | BR23: - | BS23: - | BT23: - | BU23: - | BV23: - | BW23: - | BX23: - | BY23: - | BZ23: - | CA23: - | CB23: - | CC23: - | CD23: - | CE23: - | CF23: - | CG23: - | CH23: - | CI23: - | CJ23: - | CK23: - | CL23: - | CM23: - | CN23: - | CO23: 1219.62 | CP23: 30.89 | CQ23: 32.75 | CR23: 42.59 | CS23: 402.49 | CT23: 197.07 | CU23: 241 | CV23: 114.84 | CW23: 96.19 | CX23: 217.34 | CY23: 55.09 | CZ23: 71.81 | DA23: 1058.86 | DB23: 47.74 | DC23: 52.63 | DD23: 55.17 | DE23: 58.38 | DF23: 181.77 | DG23: 278.19 | DH23: 102 | DI23: 117.66 | DJ23: 74.65 | DK23: 43.77 | DL23: 249.15 | DM23: 687.32 | DN23: 1116.07 | DO23: 54.63 | DP23: 171.35 | DQ23: 113.1 | DR23: 126.03 | DS23: 741.76 | DT23: 154.82 | DU23: 150.15 | DV23: 129.65 | DW23: 83.23 | DX23: 162.04 | DY23: 888.34 | DZ23: 480.01
A24: КРС | B24: Сельхозпредприятия | C24: ОБЛАСТЬ ҰЛЫТАУ | D24: - | E24: - | F24: - | G24: - | H24: - | I24: - | J24: - | K24: - | L24: - | M24: - | N24: - | O24: - | P24: - | Q24: - | R24: - | S24: - | T24: - | U24: - | V24: - | W24: - | X24: - | Y24: - | Z24: - | AA24: - | AB24: - | AC24: - | AD24: - | AE24: - | AF24: - | AG24: - | AH24: - | AI24: - | AJ24: - | AK24: - | AL24: - | AM24: - | AN24: - | AO24: - | AP24: - | AQ24: - | AR24: - | AS24: - | AT24: - | AU24: - | AV24: - | AW24: - | AX24: - | AY24: - | AZ24: - | BA24: - | BB24: - | BC24: - | BD24: - | BE24: - | BF24: - | BG24: - | BH24: - | BI24: - | BJ24: - | BK24: - | BL24: - | BM24: - | BN24: - | BO24: - | BP24: - | BQ24: - | BR24: - | BS24: - | BT24: - | BU24: - | BV24: - | BW24: - | BX24: - | BY24: - | BZ24: - | CA24: - | CB24: - | CC24: - | CD24: - | CE24: - | CF24: - | CG24: - | CH24: - | CI24: - | CJ24: - | CK24: - | CL24: - | CM24: - | CN24: - | CS24: 46.34 | CT24: 59.24 | CU24: 69.13 | CV24: 4.65 | CW24: 2.95 | CX24: 30.2 | CY24: 77.97 | CZ24: 0.85 | DA24: 0.84 | DB24: 0.75 | DC24: 1.25 | DD24: 1.5 | DE24: 48.3 | DF24: 62.02 | DG24: 78.1 | DH24: 2.25 | DI24: 2.5 | DJ24: 4.8 | DK24: 3 | DL24: 3.25 | DM24: 3.75 | DN24: 4 | DO24: 4 | DP24: 4.25 | DQ24: 1 | DR24: 1.25 | DS24: 1.5 | DT24: 1.25 | DU24: 5.18 | DV24: 0.75 | DW24: 1 | DX24: 1.25 | DZ24: 1
A25: КРС | B25: Сельхозпредприятия | C25: ОБЛАСТЬ АБАЙ | D25: - | E25: - | F25: - | G25: - | H25: - | I25: - | J25: - | K25: - | L25: - | M25: - | N25: - | O25: - | P25: - | Q25: - | R25: - | S25: - | T25: - | U25: - | V25: - | W25: - | X25: - | Y25: - | Z25: - | AA25: - | AB25: - | AC25: - | AD25: - | AE25: - | AF25: - | AG25: - | AH25: - | AI25: - | AJ25: - | AK25: - | AL25: - | AM25: - | AN25: - | AO25: - | AP25: - | AQ25: - | AR25: - | AS25: - | AT25: - | AU25: - | AV25: - | AW25: - | AX25: - | AY25: - | AZ25: - | BA25: - | BB25: - | BC25: - | BD25: - | BE25: - | BF25: - | BG25: - | BH25: - | BI25: - | BJ25: - | BK25: - | BL25: - | BM25: - | BN25: - | BO25: - | BP25: - | BQ25: - | BR25: - | BS25: - | BT25: - | BU25: - | BV25: - | BW25: - | BX25: - | BY25: - | BZ25: - | CA25: - | CB25: - | CC25: - | CD25: - | CE25: - | CF25: - | CG25: - | CH25: - | CI25: - | CJ25: - | CK25: - | CL25: - | CM25: - | CN25: - | CO25: 40.64 | CP25: 53.14 | CQ25: 199.93 | CR25: 77.29 | CS25: 225.89 | CT25: 138.75 | CU25: 100.86 | CV25: 21.68 | CW25: 21.91 | CX25: 76.61 | CY25: 56.39 | CZ25: 105.11 | DA25: 26.71 | DB25: 23.33 | DC25: 60.59 | DD25: 55.31 | DE25: 100.43 | DF25: 102.55 | DG25: 112.53 | DH25: 108.73 | DI25: 155.23 | DJ25: 79.87 | DK25: 73.16 | DL25: 19.51 | DM25: 61.64 | DN25: 50.54 | DO25: 62.69 | DP25: 98.45 | DQ25: 73.12 | DR25: 59.06 | DS25: 98.7 | DT25: 71.76 | DU25: 52.01 | DV25: 104.48 | DW25: 64.29 | DX25: 128.23 | DY25: 57.61 | DZ25: 43.31
A26: КРС | B26: Крестьянские или фермерские хозяйства | C26: РЕСПУБЛИКА КАЗАХСТАН | D26: 6990.34 | E26: 6827.83 | F26: 13542.06 | G26: 7934.67 | H26: 8072.49 | I26: 18498.64 | J26: 8189.79 | K26: 10061.02 | L26: 14508.32 | M26: 10327.81 | N26: 16263.61 | O26: 25697.97 | P26: 7719.13 | Q26: 6942.05 | R26: 14759.27 | S26: 8525.8 | T26: 8971.42 | U26: 20600.94 | V26: 8788.7 | W26: 10425.04 | X26: 17514.84 | Y26: 12416.53 | Z26: 18807.92 | AA26: 29871.56 | AB26: 8479.02 | AC26: 8040.39 | AD26: 19058.27 | AE26: 11052.01 | AF26: 9998.72 | AG26: 23366.13 | AH26: 8868.57 | AI26: 12156.61 | AJ26: 19206.43 | AK26: 14189.9 | AL26: 21197.77 | AM26: 36309.32 | AN26: 9010.18 | AO26: 8581.73 | AP26: 20050.29 | AQ26: 12107.72 | AR26: 10176.87 | AS26: 25047.21 | AT26: 10037.33 | AU26: 13393.54 | AV26: 22042.08 | AW26: 15025.2 | AX26: 24675.63 | AY26: 40153.33 | AZ26: 9573.49 | BA26: 9092.55 | BB26: 21219.2 | BC26: 12818.41 | BD26: 11075.47 | BE26: 29175.87 | BF26: 10746.33 | BG26: 15016.76 | BH26: 23558.12 | BI26: 16494.43 | BJ26: 25913.58 | BK26: 42548.4 | BL26: 10105.7 | BM26: 9543.22 | BN26: 22352.67 | BO26: 13404.18 | BP26: 12005.71 | BQ26: 30759.43 | BR26: 11207.43 | BS26: 15739.93 | BT26: 24497.58 | BU26: 17371.99 | BV26: 27597.25 | BW26: 47031.82 | BX26: 10558.73 | BY26: 10067.09 | BZ26: 23315.78 | CA26: 13609.62 | CB26: 12506.41 | CC26: 32806.83 | CD26: 11673.68 | CE26: 16663.03 | CF26: 25365.26 | CG26: 18198.38 | CH26: 28657.35 | CI26: 47697.04 | CJ26: 10840.52 | CK26: 10501.25 | CL26: 23958.51 | CM26: 14134.91 | CN26: 12931.73 | CO26: 34317.37 | CP26: 12655.6 | CQ26: 17347.2 | CR26: 26962.91 | CS26: 19219.67 | CT26: 29748.17 | CU26: 47705.57 | CV26: 8169.29 | CW26: 7729.37 | CX26: 18792.84 | CY26: 10715.54 | CZ26: 9804.1 | DA26: 25233.74 | DB26: 10393.58 | DC26: 13467 | DD26: 20083.58 | DE26: 15149.94 | DF26: 21550.49 | DG26: 42456.29 | DH26: 8427.67 | DI26: 8743.87 | DJ26: 19395.19 | DK26: 11734.45 | DL26: 10771.28 | DM26: 26761.43 | DN26: 11588.69 | DO26: 13916.61 | DP26: 21993.32 | DQ26: 16281.58 | DR26: 22743.54 | DS26: 44788.76 | DT26: 8900.5 | DU26: 9510.2 | DV26: 20497.2 | DW26: 12516.9 | DX26: 11316.8 | DY26: 29329.4 | DZ26: 10799.8
A27: КРС | B27: Крестьянские или фермерские хозяйства | C27: АКМОЛИНСКАЯ ОБЛАСТЬ | D27: 166.32 | E27: 177.43 | F27: 209.71 | G27: 225.46 | H27: 159.54 | I27: 291.35 | J27: 141.73 | K27: 147.51 | L27: 278.57 | M27: 274.1 | N27: 429.47 | O27: 681.4 | P27: 205 | Q27: 200.66 | R27: 239.94 | S27: 230.72 | T27: 197.38 | U27: 415.39 | V27: 198.7 | W27: 158.65 | X27: 320.79 | Y27: 300.24 | Z27: 431.12 | AA27: 784.07 | AB27: 243.77 | AC27: 275.13 | AD27: 292.07 | AE27: 246.45 | AF27: 256.12 | AG27: 470.86 | AH27: 218.97 | AI27: 197.89 | AJ27: 385.49 | AK27: 394.29 | AL27: 492.15 | AM27: 933.05 | AN27: 269.56 | AO27: 307.95 | AP27: 302.96 | AQ27: 282.49 | AR27: 242.24 | AS27: 483.73 | AT27: 187.98 | AU27: 186.69 | AV27: 384.09 | AW27: 314.3 | AX27: 480.03 | AY27: 757.18 | AZ27: 294.24 | BA27: 335.52 | BB27: 313.96 | BC27: 308.78 | BD27: 285.02 | BE27: 487.95 | BF27: 200.33 | BG27: 188.44 | BH27: 395.55 | BI27: 330.99 | BJ27: 492.99 | BK27: 749.26 | BL27: 293.5 | BM27: 343.7 | BN27: 324.2 | BO27: 318.1 | BP27: 285.8 | BQ27: 491.8 | BR27: 208.2 | BS27: 181.6 | BT27: 386.9 | BU27: 352.4 | BV27: 501.1 | BW27: 784.6 | BX27: 294.3 | BY27: 371.8 | BZ27: 336.2 | CA27: 326.7 | CB27: 287.2 | CC27: 502.1 | CD27: 211.8 | CE27: 199.1 | CF27: 395.7 | CG27: 344 | CH27: 503 | CI27: 793.8 | CJ27: 288.3 | CK27: 379.4 | CL27: 343.8 | CM27: 330.9 | CN27: 284.9 | CO27: 516.4 | CP27: 213.4 | CQ27: 198.5 | CR27: 410.6 | CS27: 331.8 | CT27: 507.7 | CU27: 782.6 | CV27: 249.17 | CW27: 308.1 | CX27: 296.49 | CY27: 243.73 | CZ27: 262.34 | DA27: 425.92 | DB27: 223.35 | DC27: 157.66 | DD27: 354.79 | DE27: 305.23 | DF27: 468.73 | DG27: 674.44 | DH27: 310.3 | DI27: 434.6 | DJ27: 341.7 | DK27: 290.6 | DL27: 288.6 | DM27: 461.9 | DN27: 229.5 | DO27: 213.2 | DP27: 413.7 | DQ27: 330.6 | DR27: 559.6 | DS27: 824.1 | DT27: 313.5 | DU27: 460.2 | DV27: 386.1 | DW27: 322.3 | DX27: 297.2 | DY27: 580.8 | DZ27: 220.8
A28: КРС | B28: Крестьянские или фермерские хозяйства | C28: АКТЮБИНСКАЯ ОБЛАСТЬ | D28: 523.08 | E28: 443.62 | F28: 616.44 | G28: 547.47 | H28: 415.09 | I28: 559.28 | J28: 525.5 | K28: 527.16 | L28: 863.7 | M28: 328.56 | N28: 1195.99 | O28: 1313.25 | P28: 457.23 | Q28: 434.54 | R28: 821.2 | S28: 645.86 | T28: 451.47 | U28: 534.94 | V28: 540.3 | W28: 512.27 | X28: 942.36 | Y28: 427.09 | Z28: 1287.97 | AA28: 1355.66 | AB28: 488.3 | AC28: 610.51 | AD28: 1116.49 | AE28: 756.61 | AF28: 713.18 | AG28: 593 | AH28: 594.22 | AI28: 598.11 | AJ28: 1059.17 | AK28: 351.84 | AL28: 1414.54 | AM28: 1513.52 | AN28: 632.52 | AO28: 633.58 | AP28: 1176.71 | AQ28: 790.78 | AR28: 745.75 | AS28: 691.06 | AT28: 1162.27 | AU28: 754.85 | AV28: 1389.48 | AW28: 425.5 | AX28: 1572.14 | AY28: 1528.76 | AZ28: 690.87 | BA28: 665.25 | BB28: 1310.82 | BC28: 868.39 | BD28: 805.99 | BE28: 833.96 | BF28: 1319.42 | BG28: 954.54 | BH28: 1730.73 | BI28: 834.4 | BJ28: 1588.68 | BK28: 1623.34 | BL28: 744.8 | BM28: 732 | BN28: 1403.3 | BO28: 998.5 | BP28: 966.5 | BQ28: 858 | BR28: 1346.7 | BS28: 1066.8 | BT28: 1776.2 | BU28: 853.4 | BV28: 1730.6 | BW28: 1667.5 | BX28: 767 | BY28: 751.5 | BZ28: 1444.6 | CA28: 1019.2 | CB28: 1034.6 | CC28: 868.6 | CD28: 1387.2 | CE28: 1092.6 | CF28: 1840.9 | CG28: 954.9 | CH28: 1748.9 | CI28: 1695.8 | CJ28: 797.5 | CK28: 776.5 | CL28: 1481 | CM28: 1043 | CN28: 1038.7 | CO28: 890.7 | CP28: 1422.2 | CQ28: 1115.1 | CR28: 1930.6 | CS28: 986.3 | CT28: 1831.3 | CU28: 1769 | CV28: 715.47 | CW28: 766.79 | CX28: 1256.61 | CY28: 1012.69 | CZ28: 944.33 | DA28: 773.89 | DB28: 1122.63 | DC28: 967.87 | DD28: 1505.43 | DE28: 761.22 | DF28: 1441.35 | DG28: 2155.41 | DH28: 767.7 | DI28: 769.9 | DJ28: 1398.8 | DK28: 1180.5 | DL28: 1024.5 | DM28: 839.9 | DN28: 1191.3 | DO28: 1031.7 | DP28: 1646 | DQ28: 943.5 | DR28: 1593 | DS28: 1893.4 | DT28: 816.5 | DU28: 819.6 | DV28: 1489.8 | DW28: 1256.8 | DX28: 1091 | DY28: 914.2 | DZ28: 1248.6
A29: КРС | B29: Крестьянские или фермерские хозяйства | C29: АЛМАТИНСКАЯ ОБЛАСТЬ | D29: 1006.07 | E29: 511.75 | F29: 6312.49 | G29: 669.05 | H29: 615.78 | I29: 4474.67 | J29: 820.6 | K29: 1912.53 | L29: 1568.1 | M29: 2324.02 | N29: 2812.75 | O29: 4090.2 | P29: 935.91 | Q29: 542.12 | R29: 6632.88 | S29: 558.04 | T29: 600.63 | U29: 4802.24 | V29: 761.78 | W29: 2002.54 | X29: 1848.3 | Y29: 3129.96 | Z29: 4182.87 | AA29: 7326.03 | AB29: 1415.41 | AC29: 644.29 | AD29: 9165.95 | AE29: 2291.1 | AF29: 625.75 | AG29: 6516.95 | AH29: 877.46 | AI29: 2989.6 | AJ29: 2459.17 | AK29: 4024.56 | AL29: 5647.78 | AM29: 10334.99 | AN29: 1433.4 | AO29: 726.14 | AP29: 9854.26 | AQ29: 3065.64 | AR29: 671.5 | AS29: 7220.02 | AT29: 960.1 | AU29: 3518.13 | AV29: 3741.36 | AW29: 4619.27 | AX29: 7235.18 | AY29: 12797.58 | AZ29: 1493.23 | BA29: 745.91 | BB29: 10296.06 | BC29: 3290.32 | BD29: 759.12 | BE29: 8910.52 | BF29: 996 | BG29: 4462.03 | BH29: 4478.53 | BI29: 4771.02 | BJ29: 6527.06 | BK29: 12448.71 | BL29: 1600.4 | BM29: 778.7 | BN29: 10499.3 | BO29: 3374.7 | BP29: 1028 | BQ29: 9432.7 | BR29: 962.7 | BS29: 4683.3 | BT29: 4657.6 | BU29: 5116.4 | BV29: 6915.6 | BW29: 13177.8 | BX29: 1664.3 | BY29: 820.2 | BZ29: 10992.2 | CA29: 3329.4 | CB29: 1113.3 | CC29: 9946.6 | CD29: 1016.4 | CE29: 5182.3 | CF29: 4961.8 | CG29: 5360 | CH29: 7209.6 | CI29: 13188.4 | CJ29: 1651.4 | CK29: 820.3 | CL29: 11293.5 | CM29: 3465.6 | CN29: 1149.8 | CO29: 5810.3 | CP29: 759.8 | CQ29: 3876.9 | CR29: 2238.2 | CS29: 3304.9 | CT29: 4287.6 | CU29: 6098.5 | CV29: 705.68 | CW29: 425.44 | CX29: 4603.18 | CY29: 1157.36 | CZ29: 500.11 | DA29: 4374.9 | DB29: 549.78 | DC29: 3102.75 | DD29: 1721.52 | DE29: 2236.16 | DF29: 3206.77 | DG29: 4540.94 | DH29: 640.2 | DI29: 425.4 | DJ29: 4592.1 | DK29: 1166.8 | DL29: 702 | DM29: 4396 | DN29: 644.2 | DO29: 3061.4 | DP29: 2726.7 | DQ29: 2375.7 | DR29: 3392.1 | DS29: 4825.9 | DT29: 695.4 | DU29: 492.3 | DV29: 4698.8 | DW29: 1185.7 | DX29: 700.3 | DY29: 4631.9 | DZ29: 652.2
A30: КРС | B30: Крестьянские или фермерские хозяйства | C30: АТЫРАУСКАЯ ОБЛАСТЬ | D30: 343.15 | E30: 145.05 | F30: 325.72 | G30: 264.21 | H30: 203.92 | I30: 269.1 | J30: 198.13 | K30: 229.7 | L30: 365 | M30: 319.46 | N30: 340.2 | O30: 726.7 | P30: 335.5 | Q30: 154.8 | R30: 330.75 | S30: 282.75 | T30: 243.1 | U30: 201.8 | V30: 223.49 | W30: 238.18 | X30: 437.16 | Y30: 343.95 | Z30: 330.7 | AA30: 567.45 | AB30: 364.95 | AC30: 164.6 | AD30: 342.93 | AE30: 306.87 | AF30: 211.66 | AG30: 216.43 | AH30: 220.26 | AI30: 242.27 | AJ30: 417.37 | AK30: 348.52 | AL30: 339.94 | AM30: 621.42 | AN30: 372.26 | AO30: 161.19 | AP30: 350.6 | AQ30: 273.8 | AR30: 209.95 | AS30: 200.62 | AT30: 224.5 | AU30: 259.09 | AV30: 446.64 | AW30: 377.04 | AX30: 402.2 | AY30: 715.52 | AZ30: 491.06 | BA30: 197.27 | BB30: 359.71 | BC30: 365.2 | BD30: 382.22 | BE30: 365.3 | BF30: 247.5 | BG30: 313.5 | BH30: 479.2 | BI30: 511.7 | BJ30: 445.5 | BK30: 727.8 | BL30: 515.6 | BM30: 233.2 | BN30: 399.5 | BO30: 390.4 | BP30: 377.5 | BQ30: 446.5 | BR30: 280.3 | BS30: 325.7 | BT30: 472.6 | BU30: 484.8 | BV30: 466 | BW30: 952.4 | BX30: 528.8 | BY30: 281.3 | BZ30: 402.9 | CA30: 360.3 | CB30: 416.9 | CC30: 464.8 | CD30: 308.5 | CE30: 349.3 | CF30: 512.2 | CG30: 571.5 | CH30: 529.8 | CI30: 970.8 | CJ30: 539.2 | CK30: 308.5 | CL30: 427.7 | CM30: 411.4 | CN30: 419.9 | CO30: 619.1 | CP30: 435.1 | CQ30: 404.1 | CR30: 529.8 | CS30: 613.5 | CT30: 567.7 | CU30: 1031.4 | CV30: 435.43 | CW30: 271.98 | CX30: 380.75 | CY30: 318.45 | CZ30: 309.21 | DA30: 537.29 | DB30: 354.37 | DC30: 336.18 | DD30: 482.02 | DE30: 503.88 | DF30: 549.47 | DG30: 899.7 | DH30: 378.5 | DI30: 376.1 | DJ30: 377.1 | DK30: 468.5 | DL30: 346.1 | DM30: 569.7 | DN30: 370.1 | DO30: 352.8 | DP30: 487.1 | DQ30: 665.2 | DR30: 617.4 | DS30: 1059.9 | DT30: 478.5 | DU30: 481.4 | DV30: 473.6 | DW30: 520 | DX30: 365.9 | DY30: 781.5 | DZ30: 397.1
A31: КРС | B31: Крестьянские или фермерские хозяйства | C31: ЗАПАДНО-КАЗАХСТАНСКАЯ ОБЛАСТЬ | D31: 784.59 | E31: 793.24 | F31: 1004.67 | G31: 1265.24 | H31: 1536 | I31: 2419.72 | J31: 824.47 | K31: 1175.26 | L31: 1960.37 | M31: 1365.39 | N31: 1541 | O31: 2182.71 | P31: 828.49 | Q31: 755.7 | R31: 1150.94 | S31: 1451.33 | T31: 1591.1 | U31: 2462.99 | V31: 781.58 | W31: 1062.95 | X31: 2178.91 | Y31: 1631 | Z31: 1388.2 | AA31: 2539.53 | AB31: 896.85 | AC31: 828.16 | AD31: 1258.48 | AE31: 1523.49 | AF31: 1592.4 | AG31: 2787.44 | AH31: 824.93 | AI31: 1025.15 | AJ31: 2409.27 | AK31: 1444.89 | AL31: 1748.92 | AM31: 3136.84 | AN31: 844.7 | AO31: 874.4 | AP31: 1311.3 | AQ31: 1537.8 | AR31: 1597.38 | AS31: 2837.8 | AT31: 860.15 | AU31: 1044.85 | AV31: 2761.1 | AW31: 1353.34 | AX31: 1735.18 | AY31: 3209.48 | AZ31: 874.15 | BA31: 887.17 | BB31: 1333.05 | BC31: 1552.05 | BD31: 1709.9 | BE31: 3474.7 | BF31: 930.69 | BG31: 1053 | BH31: 2632.9 | BI31: 1307.04 | BJ31: 1775.5 | BK31: 3384.3 | BL31: 859.8 | BM31: 883.6 | BN31: 1509.7 | BO31: 1588 | BP31: 1709.5 | BQ31: 3301.4 | BR31: 916.3 | BS31: 1072.3 | BT31: 2594.1 | BU31: 1292.9 | BV31: 1967.9 | BW31: 3787.3 | BX31: 875.2 | BY31: 961.1 | BZ31: 1709.9 | CA31: 1524.9 | CB31: 1716.9 | CC31: 3302.8 | CD31: 922.6 | CE31: 1081 | CF31: 2621.6 | CG31: 1307.4 | CH31: 1986.8 | CI31: 3818.1 | CJ31: 882.6 | CK31: 969.3 | CL31: 1717.5 | CM31: 1539.7 | CN31: 1746.2 | CO31: 3330.6 | CP31: 999.8 | CQ31: 1165.5 | CR31: 2830.7 | CS31: 1449.8 | CT31: 2130.4 | CU31: 4114 | CV31: 804.4 | CW31: 966.41 | CX31: 1511.02 | CY31: 1729.23 | CZ31: 1717.81 | DA31: 3107.65 | DB31: 1051.43 | DC31: 1169.5 | DD31: 2492.35 | DE31: 1504.88 | DF31: 2102.32 | DG31: 3759.79 | DH31: 919.2 | DI31: 1159.4 | DJ31: 1845.2 | DK31: 2016.1 | DL31: 2047.5 | DM31: 3497.8 | DN31: 1070.3 | DO31: 1193.4 | DP31: 2569.2 | DQ31: 1530.6 | DR31: 2204.7 | DS31: 4111.4 | DT31: 950.9 | DU31: 1208 | DV31: 1922.1 | DW31: 2096 | DX31: 2120.3 | DY31: 3634.7 | DZ31: 1112.8
A32: КРС | B32: Крестьянские или фермерские хозяйства | C32: ЖАМБЫЛСКАЯ ОБЛАСТЬ | D32: 628.62 | E32: 794.34 | F32: 654.4 | G32: 855.19 | H32: 607.13 | I32: 1177.53 | J32: 495.47 | K32: 999.72 | L32: 1420.37 | M32: 969.77 | N32: 2555.51 | O32: 2771.68 | P32: 758.77 | Q32: 702.62 | R32: 593.73 | S32: 897.32 | T32: 681.43 | U32: 1070.16 | V32: 489.88 | W32: 1027.8 | X32: 1580.23 | Y32: 1203.78 | Z32: 3808.14 | AA32: 3415.43 | AB32: 819.1 | AC32: 994.69 | AD32: 859.32 | AE32: 1180.83 | AF32: 1021.62 | AG32: 1455.59 | AH32: 710.7 | AI32: 1355.04 | AJ32: 1653.28 | AK32: 1451.88 | AL32: 3507.65 | AM32: 5102.53 | AN32: 976.03 | AO32: 1074.35 | AP32: 919.72 | AQ32: 1088.97 | AR32: 1075.95 | AS32: 1524.85 | AT32: 730.4 | AU32: 1406.26 | AV32: 1667.59 | AW32: 1550.99 | AX32: 3734.31 | AY32: 5295.59 | AZ32: 1012.93 | BA32: 1100.18 | BB32: 958.61 | BC32: 1126.8 | BD32: 1127.29 | BE32: 1572.19 | BF32: 739.07 | BG32: 1480.8 | BH32: 1722.02 | BI32: 1573.96 | BJ32: 3792.4 | BK32: 5440.73 | BL32: 1032.5 | BM32: 1122.7 | BN32: 979.4 | BO32: 1147.4 | BP32: 1151.8 | BQ32: 1602.5 | BR32: 754.1 | BS32: 1510.3 | BT32: 1768.7 | BU32: 1605.5 | BV32: 3871.6 | BW32: 5555.1 | BX32: 1053.2 | BY32: 1162.3 | BZ32: 1006.8 | CA32: 1188.2 | CB32: 1191.7 | CC32: 1764.4 | CD32: 767.5 | CE32: 1538.2 | CF32: 1839.6 | CG32: 1618 | CH32: 4010.4 | CI32: 5750.8 | CJ32: 1071.9 | CK32: 1184 | CL32: 1037.3 | CM32: 1214.7 | CN32: 1219.2 | CO32: 1805 | CP32: 784.5 | CQ32: 1572.7 | CR32: 1890.3 | CS32: 1661.9 | CT32: 4109.3 | CU32: 5889.5 | CV32: 523.69 | CW32: 830.96 | CX32: 875.32 | CY32: 896.54 | CZ32: 1074.4 | DA32: 1211.2 | DB32: 505.12 | DC32: 979.44 | DD32: 1270.4 | DE32: 1143.6 | DF32: 1897.9 | DG32: 4670.89 | DH32: 541.5 | DI32: 865.9 | DJ32: 904.3 | DK32: 926.7 | DL32: 1110.7 | DM32: 1257.2 | DN32: 524 | DO32: 1014.8 | DP32: 1331.3 | DQ32: 1188.8 | DR32: 1969.6 | DS32: 4848.5 | DT32: 559.5 | DU32: 1052.2 | DV32: 1017.6 | DW32: 1046.2 | DX32: 1260 | DY32: 1419.3 | DZ32: 591.4
A33: КРС | B33: Крестьянские или фермерские хозяйства | C33: КАРАГАНДИНСКАЯ ОБЛАСТЬ | D33: 884.45 | E33: 839.84 | F33: 609.7 | G33: 555.11 | H33: 753.08 | I33: 2934.28 | J33: 914.23 | K33: 1136.01 | L33: 2338.12 | M33: 970.77 | N33: 1618.62 | O33: 2367.55 | P33: 979.69 | Q33: 927.17 | R33: 702.92 | S33: 501.35 | T33: 910.91 | U33: 3334.26 | V33: 1134.03 | W33: 1203.79 | X33: 2954.45 | Y33: 1054.73 | Z33: 1753.59 | AA33: 2392.2 | AB33: 1077.25 | AC33: 995.17 | AD33: 963.69 | AE33: 599.6 | AF33: 714.76 | AG33: 3608.05 | AH33: 890.69 | AI33: 1265.5 | AJ33: 3119.38 | AK33: 1297.68 | AL33: 1782.65 | AM33: 2490.3 | AN33: 1093.05 | AO33: 1025 | AP33: 977.05 | AQ33: 616.59 | AR33: 755.97 | AS33: 3813.29 | AT33: 890.31 | AU33: 1307.13 | AV33: 3320.17 | AW33: 1351.17 | AX33: 1848.77 | AY33: 2567.64 | AZ33: 1111.78 | BA33: 1053.77 | BB33: 1102.77 | BC33: 652.24 | BD33: 799.9 | BE33: 4395.86 | BF33: 1010.76 | BG33: 1361.77 | BH33: 3439.88 | BI33: 1322.64 | BJ33: 1968.77 | BK33: 2909.63 | BL33: 1140.5 | BM33: 1087.6 | BN33: 1403.9 | BO33: 657.7 | BP33: 851.9 | BQ33: 4904.8 | BR33: 1124.1 | BS33: 1427.2 | BT33: 3613.6 | BU33: 1428.2 | BV33: 2159.1 | BW33: 3105.2 | BX33: 1188.7 | BY33: 1140.2 | BZ33: 1458.5 | CA33: 683.8 | CB33: 901.1 | CC33: 5138.7 | CD33: 1193 | CE33: 1532.8 | CF33: 3816.7 | CG33: 1502.4 | CH33: 2296.4 | CI33: 3278.6 | CJ33: 1239.9 | CK33: 1198.4 | CL33: 1519.1 | CM33: 729.5 | CN33: 949.2 | CO33: 3814.7 | CP33: 1086.5 | CQ33: 1235.4 | CR33: 2742.6 | CS33: 1279.7 | CT33: 1969.7 | CU33: 1970.5 | CV33: 572.27 | CW33: 602.86 | CX33: 995.52 | CY33: 396.49 | CZ33: 384.46 | DA33: 3143.04 | DB33: 923.5 | DC33: 1070.77 | DD33: 2202.55 | DE33: 1026.52 | DF33: 1650.84 | DG33: 1770.9 | DH33: 578.8 | DI33: 617.5 | DJ33: 1026 | DK33: 398.1 | DL33: 388.7 | DM33: 3162.9 | DN33: 942 | DO33: 1116.7 | DP33: 2289.8 | DQ33: 1071 | DR33: 1669.2 | DS33: 1827 | DT33: 584.8 | DU33: 644.9 | DV33: 1041.6 | DW33: 404.9 | DX33: 411.9 | DY33: 3320.2 | DZ33: 954.8
A34: КРС | B34: Крестьянские или фермерские хозяйства | C34: КОСТАНАЙСКАЯ ОБЛАСТЬ | D34: 104.43 | E34: 129.37 | F34: 112.02 | G34: 126.6 | H34: 235.85 | I34: 192.68 | J34: 120.7 | K34: 73.62 | L34: 136.01 | M34: 92.56 | N34: 269.18 | O34: 682.43 | P34: 103.88 | Q34: 159.45 | R34: 119.34 | S34: 131.1 | T34: 205.32 | U34: 1322.69 | V34: 112.09 | W34: 29.46 | X34: 162.4 | Y34: 101.3 | Z34: 278.98 | AA34: 803.42 | AB34: 111.07 | AC34: 153.62 | AD34: 144.41 | AE34: 143.86 | AF34: 232.59 | AG34: 271.75 | AH34: 72.62 | AI34: 42.73 | AJ34: 137.4 | AK34: 56.19 | AL34: 308.19 | AM34: 789 | AN34: 148.69 | AO34: 165.48 | AP34: 155.82 | AQ34: 155.21 | AR34: 250.96 | AS34: 291.96 | AT34: 74.88 | AU34: 44.13 | AV34: 141.34 | AW34: 57.94 | AX34: 318.69 | AY34: 815.4 | AZ34: 153.7 | BA34: 171.21 | BB34: 161.08 | BC34: 160.36 | BD34: 259.13 | BE34: 301.47 | BF34: 78.34 | BG34: 46.16 | BH34: 145.83 | BI34: 59.95 | BJ34: 329.77 | BK34: 843.93 | BL34: 164.9 | BM34: 183.7 | BN34: 172.3 | BO34: 171.5 | BP34: 273.7 | BQ34: 318.3 | BR34: 82.2 | BS34: 48.4 | BT34: 153.2 | BU34: 62.9 | BV34: 346.4 | BW34: 884.5 | BX34: 174.1 | BY34: 193.8 | BZ34: 181.5 | CA34: 180.3 | CB34: 287.4 | CC34: 334 | CD34: 91.7 | CE34: 54 | CF34: 170 | CG34: 69.6 | CH34: 382.2 | CI34: 951.7 | CJ34: 191.2 | CK34: 212.8 | CL34: 198.4 | CM34: 196.9 | CN34: 313.7 | CO34: 363.8 | CP34: 104.6 | CQ34: 61.6 | CR34: 194 | CS34: 79.3 | CT34: 435.5 | CU34: 981.9 | CV34: 50.36 | CW34: 63.62 | CX34: 70.39 | CY34: 87.29 | CZ34: 110.17 | DA34: 118.2 | DB34: 29.79 | DC34: 20.38 | DD34: 81.45 | DE34: 30.53 | DF34: 135.41 | DG34: 287.7 | DH34: 51.7 | DI34: 65.7 | DJ34: 73.1 | DK34: 90.7 | DL34: 113.9 | DM34: 124.5 | DN34: 30.2 | DO34: 20.7 | DP34: 82.9 | DQ34: 31 | DR34: 137.7 | DS34: 292.5 | DT34: 56 | DU34: 71.1 | DV34: 79.2 | DW34: 98.3 | DX34: 123.5 | DY34: 135.5 | DZ34: 29.9
A35: КРС | B35: Крестьянские или фермерские хозяйства | C35: КЫЗЫЛОРДИНСКАЯ ОБЛАСТЬ | D35: 100 | E35: 89.24 | F35: 162.92 | G35: 193.43 | H35: 99.46 | I35: 214.1 | J35: 158.07 | K35: 203.86 | L35: 134.16 | M35: 98.43 | N35: 89.7 | O35: 151.42 | P35: 115.87 | Q35: 113.55 | R35: 156.28 | S35: 149.03 | T35: 132.84 | U35: 269.92 | V35: 149.71 | W35: 187.69 | X35: 199.4 | Y35: 204.35 | Z35: 181.7 | AA35: 245.31 | AB35: 138.19 | AC35: 151.45 | AD35: 138.82 | AE35: 208.44 | AF35: 170.67 | AG35: 227.62 | AH35: 123.16 | AI35: 180.9 | AJ35: 246.01 | AK35: 199.77 | AL35: 262.29 | AM35: 174.48 | AN35: 143.96 | AO35: 147.17 | AP35: 140.56 | AQ35: 201.8 | AR35: 172.54 | AS35: 209.2 | AT35: 114.05 | AU35: 189.2 | AV35: 237.56 | AW35: 185.78 | AX35: 249.83 | AY35: 172.92 | AZ35: 145.95 | BA35: 146.53 | BB35: 139.41 | BC35: 211.46 | BD35: 175.92 | BE35: 212.89 | BF35: 114.41 | BG35: 184.85 | BH35: 233.02 | BI35: 181.32 | BJ35: 255.45 | BK35: 178.6 | BL35: 148.2 | BM35: 150.3 | BN35: 143 | BO35: 202.8 | BP35: 179.7 | BQ35: 207.6 | BR35: 125.9 | BS35: 201.1 | BT35: 243 | BU35: 206.1 | BV35: 294.5 | BW35: 221 | BX35: 166.3 | BY35: 172 | BZ35: 137.9 | CA35: 205.6 | CB35: 203.9 | CC35: 243.2 | CD35: 129.5 | CE35: 204.7 | CF35: 255.7 | CG35: 205.4 | CH35: 308.2 | CI35: 245.7 | CJ35: 171.2 | CK35: 178.5 | CL35: 143.2 | CM35: 209.1 | CN35: 209 | CO35: 286.5 | CP35: 130.8 | CQ35: 208.5 | CR35: 287.2 | CS35: 213.3 | CT35: 340.9 | CU35: 273.6 | CV35: 145.73 | CW35: 142.25 | CX35: 118.37 | CY35: 168.28 | CZ35: 156.35 | DA35: 179.75 | DB35: 109.5 | DC35: 153.13 | DD35: 219.45 | DE35: 170.64 | DF35: 286.98 | DG35: 180.79 | DH35: 138 | DI35: 154.2 | DJ35: 124.3 | DK35: 168.2 | DL35: 168.7 | DM35: 183.5 | DN35: 137.7 | DO35: 103.6 | DP35: 224.1 | DQ35: 176.6 | DR35: 294.3 | DS35: 509.4 | DT35: 144.5 | DU35: 166.8 | DV35: 127.7 | DW35: 175.1 | DX35: 196.9 | DY35: 189.2 | DZ35: 158.2
A36: КРС | B36: Крестьянские или фермерские хозяйства | C36: МАНГИСТАУСКАЯ ОБЛАСТЬ | D36: 11.76 | E36: 61.32 | F36: 84.04 | G36: 152.56 | H36: 34.97 | I36: 42.3 | J36: 57.53 | K36: 28.49 | L36: 11.29 | M36: 167.79 | N36: 49.07 | O36: 120.13 | P36: 11.83 | Q36: 12.13 | R36: 18.9 | S36: 14.38 | T36: 14.37 | U36: 17.2 | V36: 15.23 | W36: 15.23 | X36: 26.5 | Y36: 18.9 | Z36: 27.36 | AA36: 200.78 | AB36: 12.69 | AC36: 13.25 | AD36: 19.45 | AE36: 15.23 | AF36: 15.23 | AG36: 18.32 | AH36: 15.79 | AI36: 15.79 | AJ36: 26.78 | AK36: 19.46 | AL36: 32.72 | AM36: 259.43 | AN36: 20.03 | AO36: 22.83 | AP36: 25.38 | AQ36: 21.16 | AR36: 13.82 | AS36: 24.81 | AT36: 19.74 | AU36: 18.89 | AV36: 47.93 | AW36: 26.51 | AX36: 55 | AY36: 271.84 | AZ36: 21.72 | BA36: 26.8 | BB36: 40.88 | BC36: 48.5 | BD36: 15.5 | BE36: 54.7 | BF36: 24.54 | BG36: 23.97 | BH36: 61.76 | BI36: 32.14 | BJ36: 88.83 | BK36: 286.79 | BL36: 38.4 | BM36: 31 | BN36: 40.9 | BO36: 49.4 | BP36: 17.2 | BQ36: 58.7 | BR36: 28.2 | BS36: 27.4 | BT36: 97 | BU36: 32.2 | BV36: 91.9 | BW36: 296.7 | BX36: 40.3 | BY36: 34.4 | BZ36: 42.6 | CA36: 52.7 | CB36: 17.8 | CC36: 74.4 | CD36: 33.6 | CE36: 29.6 | CF36: 99 | CG36: 49.9 | CH36: 106.6 | CI36: 327.7 | CJ36: 43.7 | CK36: 37.2 | CL36: 45.1 | CM36: 55.8 | CN36: 18.9 | CO36: 77.6 | CP36: 34.7 | CQ36: 30.7 | CR36: 102.4 | CS36: 52.7 | CT36: 111.7 | CU36: 337.8 | CV36: 42.18 | CW36: 32.33 | CX36: 44.09 | CY36: 57.39 | CZ36: 18.55 | DA36: 78.37 | DB36: 34.49 | DC36: 32.28 | DD36: 105.78 | DE36: 53.39 | DF36: 83.79 | DG36: 214.9 | DH36: 40 | DI36: 33.6 | DJ36: 44.8 | DK36: 57.2 | DL36: 18 | DM36: 77.6 | DN36: 32.7 | DO36: 30.5 | DP36: 100.7 | DQ36: 50.8 | DR36: 80.1 | DS36: 208.7 | DT36: 42 | DU36: 35.5 | DV36: 47.4 | DW36: 60.1 | DX36: 13.8 | DY36: 81.5 | DZ36: 34.1
